<?xml version="1.0" encoding="utf-8"?>
<!-- This URDF was automatically created by SolidWorks to URDF Exporter! Originally created by Stephen Brawner (brawner@gmail.com) 
     Commit Version: 1.4.4-24-g24328f6  Build Version: 1.5.7084.36479
     For more information, please see http://wiki.ros.org/sw_urdf_exporter -->
<robot
  name="urdf_arm_1">
  <link
    name="base_link">
    <inertial>
      <origin
        xyz="0.011412 0.0019213 -0.1202"
        rpy="0 0 0" />
      <mass
        value="10.672" />
      <inertia
        ixx="0.093685"
        ixy="5.5456E-05"
        ixz="1.1698E-05"
        iyy="0.051517"
        iyz="-0.0032445"
        izz="0.098201" />
    </inertial>
    <visual>
      <origin
        xyz="0 0 0"
        rpy="0 0 0" />
      <geometry>
        <mesh
          filename="package://urdf_arm_1/meshes/base_link.STL" />
      </geometry>
      <material
        name="">
        <color
          rgba="0.79216 0.81961 0.93333 1" />
      </material>
    </visual>
    <collision>
      <origin
        xyz="0 0 0"
        rpy="0 0 0" />
      <geometry>
        <mesh
          filename="package://urdf_arm_1/meshes/base_link.STL" />
      </geometry>
    </collision>
  </link>
  <link
    name="link_1">
    <inertial>
      <origin
        xyz="-1.3035E-09 0.0037062 0.017301"
        rpy="0 0 0" />
      <mass
        value="0.30463" />
      <inertia
        ixx="0.00022794"
        ixy="8.3291E-10"
        ixz="1.3386E-10"
        iyy="0.00033807"
        iyz="-7.9381E-06"
        izz="0.0005198" />
    </inertial>
    <visual>
      <origin
        xyz="0 0 0"
        rpy="0 0 0" />
      <geometry>
        <mesh
          filename="package://urdf_arm_1/meshes/link_1.STL" />
      </geometry>
      <material
        name="">
        <color
          rgba="0.79216 0.81961 0.93333 1" />
      </material>
    </visual>
    <collision>
      <origin
        xyz="0 0 0"
        rpy="0 0 0" />
      <geometry>
        <mesh
          filename="package://urdf_arm_1/meshes/link_1.STL" />
      </geometry>
    </collision>
  </link>
  <joint
    name="joint_1"
    type="revolute">
    <origin
      xyz="0.0075022 -8.0428E-05 0.0090542"
      rpy="0 0 0" />
    <parent
      link="base_link" />
    <child
      link="link_1" />
    <axis
      xyz="0 0 0" />
    <limit
      lower="0"
      upper="0"
      effort="0"
      velocity="0" />
    <safety_controller
      k_velocity="0" />
  </joint>
  <link
    name="link_2">
    <inertial>
      <origin
        xyz="0.01008 -0.087456 0.24001"
        rpy="0 0 0" />
      <mass
        value="0.47708" />
      <inertia
        ixx="0.0022814"
        ixy="3.6814E-07"
        ixz="-5.7305E-07"
        iyy="0.0019239"
        iyz="0.00064529"
        izz="0.00038584" />
    </inertial>
    <visual>
      <origin
        xyz="0 0 0"
        rpy="0 0 0" />
      <geometry>
        <mesh
          filename="package://urdf_arm_1/meshes/link_2.STL" />
      </geometry>
      <material
        name="">
        <color
          rgba="0.62745 0.62745 0.62745 1" />
      </material>
    </visual>
    <collision>
      <origin
        xyz="0 0 0"
        rpy="0 0 0" />
      <geometry>
        <mesh
          filename="package://urdf_arm_1/meshes/link_2.STL" />
      </geometry>
    </collision>
  </link>
  <joint
    name="joint_2"
    type="revolute">
    <origin
      xyz="-0.01 0.020897 -0.020746"
      rpy="0 0 0" />
    <parent
      link="link_1" />
    <child
      link="link_2" />
    <axis
      xyz="0 0 0" />
    <limit
      lower="0"
      upper="0"
      effort="0"
      velocity="0" />
    <safety_controller
      k_velocity="0" />
  </joint>
  <link
    name="link_3">
    <inertial>
      <origin
        xyz="0.017445 0.010484 -0.053632"
        rpy="0 0 0" />
      <mass
        value="0.21849" />
      <inertia
        ixx="0.000947"
        ixy="-6.0335E-07"
        ixz="-1.8944E-06"
        iyy="0.0008941"
        iyz="-0.00015221"
        izz="5.7673E-05" />
    </inertial>
    <visual>
      <origin
        xyz="0 0 0"
        rpy="0 0 0" />
      <geometry>
        <mesh
          filename="package://urdf_arm_1/meshes/link_3.STL" />
      </geometry>
      <material
        name="">
        <color
          rgba="1 1 1 1" />
      </material>
    </visual>
    <collision>
      <origin
        xyz="0 0 0"
        rpy="0 0 0" />
      <geometry>
        <mesh
          filename="package://urdf_arm_1/meshes/link_3.STL" />
      </geometry>
    </collision>
  </link>
  <joint
    name="joint_3"
    type="revolute">
    <origin
      xyz="-0.0067069 -0.18532 0.27357"
      rpy="0 0 0" />
    <parent
      link="link_2" />
    <child
      link="link_3" />
    <axis
      xyz="0 0 0" />
    <limit
      lower="0"
      upper="0"
      effort="0"
      velocity="0" />
    <safety_controller
      k_velocity="0" />
  </joint>
  <link
    name="link_4">
    <inertial>
      <origin
        xyz="0.014177 -0.024536 -0.01537"
        rpy="0 0 0" />
      <mass
        value="0.057881" />
      <inertia
        ixx="1.2248E-05"
        ixy="-5.1474E-09"
        ixz="-2.1323E-09"
        iyy="1.1754E-05"
        iyz="1.3344E-11"
        izz="4.9828E-06" />
    </inertial>
    <visual>
      <origin
        xyz="0 0 0"
        rpy="0 0 0" />
      <geometry>
        <mesh
          filename="package://urdf_arm_1/meshes/link_4.STL" />
      </geometry>
      <material
        name="">
        <color
          rgba="1 1 1 1" />
      </material>
    </visual>
    <collision>
      <origin
        xyz="0 0 0"
        rpy="0 0 0" />
      <geometry>
        <mesh
          filename="package://urdf_arm_1/meshes/link_4.STL" />
      </geometry>
    </collision>
  </link>
  <joint
    name="joint_4"
    type="revolute">
    <origin
      xyz="0.0026523 -0.019276 -0.2241"
      rpy="0 0 0" />
    <parent
      link="link_3" />
    <child
      link="link_4" />
    <axis
      xyz="-0.99994 0.010723 0.00029305" />
    <limit
      lower="-3.6652"
      upper="0.69813"
      effort="0"
      velocity="0" />
    <safety_controller
      k_velocity="0" />
  </joint>
</robot>