<?xml version="1.0" encoding="utf-8"?>
<!-- This URDF was automatically created by SolidWorks to URDF Exporter! Originally created by Stephen Brawner (brawner@gmail.com) 
     Commit Version: 1.4.4-24-g24328f6  Build Version: 1.5.7084.36479
     For more information, please see http://wiki.ros.org/sw_urdf_exporter -->
<robot
  name="whole body stand urdf">
  <link
    name="base_link">
    <inertial>
      <origin
        xyz="0.052311 -0.020358 0.021084"
        rpy="0 0 0" />
      <mass
        value="10.672" />
      <inertia
        ixx="0.05129"
        ixy="-5.5239E-05"
        ixz="0.003337"
        iyy="0.093685"
        iyz="1.1758E-05"
        izz="0.098428" />
    </inertial>
    <visual>
      <origin
        xyz="0 0 0"
        rpy="0 0 0" />
      <geometry>
        <mesh
          filename="package://whole body stand urdf/meshes/base_link.STL" />
      </geometry>
      <material
        name="">
        <color
          rgba="1 1 1 1" />
      </material>
    </visual>
    <collision>
      <origin
        xyz="0 0 0"
        rpy="0 0 0" />
      <geometry>
        <mesh
          filename="package://whole body stand urdf/meshes/base_link.STL" />
      </geometry>
    </collision>
  </link>
  <link
    name="link_1">
    <inertial>
      <origin
        xyz="-1.3035E-09 0.0037062 0.017301"
        rpy="0 0 0" />
      <mass
        value="0.30463" />
      <inertia
        ixx="0.00022794"
        ixy="8.3291E-10"
        ixz="1.3386E-10"
        iyy="0.00033807"
        iyz="-7.9381E-06"
        izz="0.0005198" />
    </inertial>
    <visual>
      <origin
        xyz="0 0 0"
        rpy="0 0 0" />
      <geometry>
        <mesh
          filename="package://whole body stand urdf/meshes/link_1.STL" />
      </geometry>
      <material
        name="">
        <color
          rgba="0.79216 0.81961 0.93333 1" />
      </material>
    </visual>
    <collision>
      <origin
        xyz="0 0 0"
        rpy="0 0 0" />
      <geometry>
        <mesh
          filename="package://whole body stand urdf/meshes/link_1.STL" />
      </geometry>
    </collision>
  </link>
  <joint
    name="joint_1"
    type="revolute">
    <origin
      xyz="0.055262 -0.024268 0.14938"
      rpy="0.0055232 0.0003523 1.5601" />
    <parent
      link="base_link" />
    <child
      link="link_1" />
    <axis
      xyz="0 0 0" />
    <limit
      lower="0"
      upper="0"
      effort="0"
      velocity="0" />
    <safety_controller
      k_velocity="0" />
  </joint>
  <link
    name="link_2">
    <inertial>
      <origin
        xyz="0.25545 -9.4E-05 -0.01"
        rpy="0 0 0" />
      <mass
        value="0.47708" />
      <inertia
        ixx="0.00015098"
        ixy="6.6166E-16"
        ixz="4.8079E-15"
        iyy="0.0021588"
        iyz="-1.4995E-07"
        izz="0.0022814" />
    </inertial>
    <visual>
      <origin
        xyz="0 0 0"
        rpy="0 0 0" />
      <geometry>
        <mesh
          filename="package://whole body stand urdf/meshes/link_2.STL" />
      </geometry>
      <material
        name="">
        <color
          rgba="0.62745 0.62745 0.62745 1" />
      </material>
    </visual>
    <collision>
      <origin
        xyz="0 0 0"
        rpy="0 0 0" />
      <geometry>
        <mesh
          filename="package://whole body stand urdf/meshes/link_2.STL" />
      </geometry>
    </collision>
  </link>
  <joint
    name="joint_2"
    type="revolute">
    <origin
      xyz="-0.01 0.020897 -0.020746"
      rpy="1.5708 -1.2217 -1.5708" />
    <parent
      link="link_1" />
    <child
      link="link_2" />
    <axis
      xyz="0 0 0" />
    <limit
      lower="0"
      upper="0"
      effort="0"
      velocity="0" />
    <safety_controller
      k_velocity="0" />
  </joint>
  <link
    name="link_3">
    <inertial>
      <origin
        xyz="-0.1422 0.1064 -0.0075"
        rpy="0 0 0" />
      <mass
        value="0.21849" />
      <inertia
        ixx="0.00035027"
        ixy="0.00042695"
        ixz="-5.2502E-09"
        iyy="0.0006015"
        iyz="-7.017E-09"
        izz="0.00094701" />
    </inertial>
    <visual>
      <origin
        xyz="0 0 0"
        rpy="0 0 0" />
      <geometry>
        <mesh
          filename="package://whole body stand urdf/meshes/link_3.STL" />
      </geometry>
      <material
        name="">
        <color
          rgba="0.62745 0.62745 0.62745 1" />
      </material>
    </visual>
    <collision>
      <origin
        xyz="0 0 0"
        rpy="0 0 0" />
      <geometry>
        <mesh
          filename="package://whole body stand urdf/meshes/link_3.STL" />
      </geometry>
    </collision>
  </link>
  <joint
    name="joint_3"
    type="revolute">
    <origin
      xyz="0.42023 -9.4E-05 -0.0030409"
      rpy="0 0 1.1659" />
    <parent
      link="link_2" />
    <child
      link="link_3" />
    <axis
      xyz="0 0 0" />
    <limit
      lower="0"
      upper="0"
      effort="0"
      velocity="0" />
    <safety_controller
      k_velocity="0" />
  </joint>
  <link
    name="link_4">
    <inertial>
      <origin
        xyz="0.024383 -0.015366 -0.0075207"
        rpy="0 0 0" />
      <mass
        value="0.057881" />
      <inertia
        ixx="1.1754E-05"
        ixy="-8.0339E-12"
        ixz="1.4951E-10"
        iyy="4.9828E-06"
        iyz="3.3125E-12"
        izz="1.2248E-05" />
    </inertial>
    <visual>
      <origin
        xyz="0 0 0"
        rpy="0 0 0" />
      <geometry>
        <mesh
          filename="package://whole body stand urdf/meshes/link_4.STL" />
      </geometry>
      <material
        name="">
        <color
          rgba="1 1 1 1" />
      </material>
    </visual>
    <collision>
      <origin
        xyz="0 0 0"
        rpy="0 0 0" />
      <geometry>
        <mesh
          filename="package://whole body stand urdf/meshes/link_4.STL" />
      </geometry>
    </collision>
  </link>
  <joint
    name="joint_4"
    type="revolute">
    <origin
      xyz="-0.2807 0.2102 0"
      rpy="0 0 -2.3877" />
    <parent
      link="link_3" />
    <child
      link="link_4" />
    <axis
      xyz="0 0 1" />
    <limit
      lower="0"
      upper="3.14"
      effort="0"
      velocity="0" />
    <safety_controller
      k_velocity="0" />
  </joint>
</robot>